<?xml version="1.0" encoding="utf-8"?>
<robot name="Box2">
  <link name="base_link">
    <inertial>
      <origin rpy="0 0 0" xyz="0 0 0" />
      <mass value="1" />
      <inertia ixx="1" ixy="0" ixz="0" iyy="1" iyz="0" izz="1" />
    </inertial>
    <visual name="base_link">
      <geometry>
        <mesh filename="package://meshes/base_link.fbx" scale="1 1 1" />
      </geometry>
    </visual>
    <collision name="base_link">
      <geometry>
        <mesh filename="package://meshes/base_link.obj" scale="1 1 1" />
      </geometry>
    </collision>
  </link>
  <link name="link1">
    <inertial>
      <origin rpy="0 0 0" xyz="0 0 0" />
      <mass value="1" />
      <inertia ixx="1" ixy="0" ixz="0" iyy="1" iyz="0" izz="1" />
    </inertial>
    <visual name="link1">
      <origin xyz="-0.0155 0.041569 0" />
      <geometry>
        <mesh filename="package://meshes/link1.fbx" scale="1 1 1" />
      </geometry>
    </visual>
    <collision name="link1">
      <origin xyz="-0.0155 0.041569 0" />
      <geometry>
        <mesh filename="package://meshes/link1.obj" scale="1 1 1" />
      </geometry>
    </collision>
  </link>
  <joint name="base_link_link1_joint" type="revolute">
    <origin xyz="0.0155 -0.041569 0" />
    <parent link="base_link" />
    <child link="link1" />
    <axis xyz="-0.002666 0 -0.999996" />
    <limit lower="-0.279253" upper="3.141593" effort="1000" velocity="1000" />
  </joint>
</robot>