<?xml version="1.0" ?>
<robot name="box5">
	<link name="base_link">
		<visual>
			<origin rpy="0.0 0.0 0.0" xyz="6.761317442719996e-05 0.0001069107436150071 0.00043863180586354173"/>
			<geometry>
				<mesh filename="part_meshes/base_link.ply"/>
			</geometry>
		</visual>
		<inertial>
			<origin rpy="0 0 0" xyz="0 0 0"/>
			<mass value="0.0"/>
			<inertia ixx="0.0" ixy="0.0" ixz="0.0" iyy="0.0" iyz="0.0" izz="0.0"/>
		</inertial>
	</link>
	<link name="link1">
		<visual>
			<origin rpy="0.0 0.0 0.0" xyz="0.00014484716847859585 9.709233155211641e-05 0.0004815957250782986"/>
			<geometry>
				<mesh filename="part_meshes/link1.ply"/>
			</geometry>
		</visual>
		<inertial>
			<origin rpy="0 0 0" xyz="0 0 0"/>
			<mass value="0.0"/>
			<inertia ixx="0.0" ixy="0.0" ixz="0.0" iyy="0.0" iyz="0.0" izz="0.0"/>
		</inertial>
	</link>
	<link name="base_link">
		<visual>
			<origin rpy="0.0 0.0 0.0" xyz="6.761317442719996e-05 0.0001069107436150071 0.00043863180586354173"/>
			<geometry>
				<mesh filename="part_meshes/base_link.ply"/>
			</geometry>
		</visual>
		<inertial>
			<origin rpy="0 0 0" xyz="0 0 0"/>
			<mass value="0.0"/>
			<inertia ixx="0.0" ixy="0.0" ixz="0.0" iyy="0.0" iyz="0.0" izz="0.0"/>
		</inertial>
	</link>
	<link name="link1">
		<visual>
			<origin rpy="0.0 0.0 0.0" xyz="0.00014484716847859585 9.709233155211641e-05 0.0004815957250782986"/>
			<geometry>
				<mesh filename="part_meshes/link1.ply"/>
			</geometry>
		</visual>
		<inertial>
			<origin rpy="0 0 0" xyz="0 0 0"/>
			<mass value="0.0"/>
			<inertia ixx="0.0" ixy="0.0" ixz="0.0" iyy="0.0" iyz="0.0" izz="0.0"/>
		</inertial>
	</link>
	<joint name="base_link|prismatic|link1" type="prismatic">
		<parent link="base_link"/>
		<child link="link1"/>
		<origin rpy="0 0 0" xyz="0.00011012612040066509 -1.8091996244159874e-05 0.00042770598994608774"/>
		<axis xyz="-0.06901859263419541 0.9397431016231858 0.3351964608197938"/>
		<limit effort="1.0" lower="-1.0" upper="1.0" velocity="1000"/>
	</joint>
	<joint name="base_link|revolute|link1" type="revolute">
		<parent link="base_link"/>
		<child link="link1"/>
		<origin rpy="0 0 0" xyz="0.00011012612040066509 -1.8091996244159874e-05 0.00042770598994608774"/>
		<axis xyz="-0.06901859263419541 0.9397431016231858 0.3351964608197938"/>
		<limit effort="1.0" lower="-1.0" upper="1.0" velocity="1000"/>
	</joint>
</robot>
